from django.core.exceptions import ValidationError

from forms_part_2_demos.web.models import Todo


def validate_max_todos_per_person(assignee):
    if assignee.todo_set.count() >= Todo.MAX_TODOS_COUNT_PER_PERSON:
        raise ValidationError(f'{assignee} has already max todos assigned')
